Workbook

Sheet 수업개요
A1: 정보 × 물리 융합수업 — 코드로 만드는 운동 시뮬레이터
A2: 고등학교 | 8차시 × 50분 | 2개 과정(물리 중심 / 정보 중심) | 웹앱 기반 학생 자기주도 진행
A4: 과정 비교
A5: 구분 | B5: 물리 중심 과정 | C5: 정보 중심 과정
A6: 주(主) 교과 | B6: 「역학과 에너지」 | C6: 「정보」
A7: 보조 역할 | B7: 정보 — 계산 도구로 사용 | C7: 물리 — 문제 상황으로 사용
A8: 핵심 목표 | B8: 모형을 세우고 실험으로 검증하며 물리 개념을 확장한다 | C8: 물리 현상을 소재로 컴퓨팅 사고력을 기른다
A9: 총 차시 | B9: 8 | C9: 8
A10: 총 단계 수 | B10: 52 | C10: 37
A11: 총 수업 시간(분) | B11: =B9*50 | C11: =C9*50
A13: 차시별 시간 배분 (분) — 각 지도안 시트에서 자동 집계
A14: 차시 | B14: 1차시 | C14: 2차시 | D14: 3차시 | E14: 4차시 | F14: 5차시 | G14: 6차시 | H14: 7차시 | I14: 8차시 | J14: 합계
A15: 물리 중심 | B15: =SUMIF(물리중심_지도안!$A:$A,1,물리중심_지도안!$F:$F) | C15: =SUMIF(물리중심_지도안!$A:$A,2,물리중심_지도안!$F:$F) | D15: =SUMIF(물리중심_지도안!$A:$A,3,물리중심_지도안!$F:$F) | E15: =SUMIF(물리중심_지도안!$A:$A,4,물리중심_지도안!$F:$F) | F15: =SUMIF(물리중심_지도안!$A:$A,5,물리중심_지도안!$F:$F) | G15: =SUMIF(물리중심_지도안!$A:$A,6,물리중심_지도안!$F:$F) | H15: =SUMIF(물리중심_지도안!$A:$A,7,물리중심_지도안!$F:$F) | I15: =SUMIF(물리중심_지도안!$A:$A,8,물리중심_지도안!$F:$F) | J15: =SUM(B15:I15)
A16: 정보 중심 | B16: =SUMIF(정보중심_지도안!$A:$A,1,정보중심_지도안!$F:$F) | C16: =SUMIF(정보중심_지도안!$A:$A,2,정보중심_지도안!$F:$F) | D16: =SUMIF(정보중심_지도안!$A:$A,3,정보중심_지도안!$F:$F) | E16: =SUMIF(정보중심_지도안!$A:$A,4,정보중심_지도안!$F:$F) | F16: =SUMIF(정보중심_지도안!$A:$A,5,정보중심_지도안!$F:$F) | G16: =SUMIF(정보중심_지도안!$A:$A,6,정보중심_지도안!$F:$F) | H16: =SUMIF(정보중심_지도안!$A:$A,7,정보중심_지도안!$F:$F) | I16: =SUMIF(정보중심_지도안!$A:$A,8,정보중심_지도안!$F:$F) | J16: =SUM(B16:I16)
A18: 단계 유형별 구성 (개수)
A19: 유형 | B19: 물리 중심 | C19: 정보 중심
A20: 탐구·활동 | B20: =COUNTIF(물리중심_지도안!$E:$E,$A20) | C20: =COUNTIF(정보중심_지도안!$E:$E,$A20)
A21: 코딩 미션 | B21: =COUNTIF(물리중심_지도안!$E:$E,$A21) | C21: =COUNTIF(정보중심_지도안!$E:$E,$A21)
A22: 측정값 제출 | B22: =COUNTIF(물리중심_지도안!$E:$E,$A22) | C22: =COUNTIF(정보중심_지도안!$E:$E,$A22)
A23: 서술 작성 | B23: =COUNTIF(물리중심_지도안!$E:$E,$A23) | C23: =COUNTIF(정보중심_지도안!$E:$E,$A23)
A24: 합계 | B24: =SUM(B20:B23) | C24: =SUM(C20:C23)
A26: ※ 성취기준 확인 상태
A27: 물리(역학과 에너지) 성취기준은 교육부 고시 교육과정 원문과 대조해 확인했습니다. 정보 성취기준은 대조할 자료가 없어 번호를 확정하지 못했으니 NCIC에서 확인해 주십시오. 자세한 내용은 [성취기준_매핑] 시트 하단을 참고하십시오.
A30: 라이선스 : CC BY-NC-SA 4.0 (출처 표시 · 비영리 · 동일조건변경허락)

Sheet 물리중심_지도안
A1: 물리 중심 과정 — 차시별 지도안
A2: 과목 「역학과 에너지」 주(主) · 정보는 계산 도구 | 각 차시 합계 50분 (소계는 수식으로 자동 계산)
A4: 차시 | B4: 차시 주제 | C4: 단계 | D4: 단계 활동명 | E4: 단계 유형 | F4: 시간(분)
A5: 1 | B5: 현상을 관찰하고 알고리즘 설계하기 | C5: 1 | D5: 오늘의 질문에 예측해 봅시다 | E5: 탐구·활동 | F5: 3
A6: 1 | C6: 2 | D6: 시뮬레이터를 조작해 봅시다 | E6: 탐구·활동 | F6: 6
A7: 1 | C7: 3 | D7: 공기저항이 없을 때, 가장 멀리 가는 각도는? | E7: 탐구·활동 | F7: 6
A8: 1 | C8: 4 | D8: 그런데 공기저항을 넣으면? | E8: 탐구·활동 | F8: 6
A9: 1 | C9: 5 | D9: 왜 공식으로는 풀 수 없을까 | E9: 탐구·활동 | F9: 5
A10: 1 | C10: 6 | D10: 알고리즘 순서 맞추기 | E10: 탐구·활동 | F10: 12
A11: 1 | C11: 7 | D11: 컴퓨터가 되어 한 스텝만 손으로 계산하기 | E11: 탐구·활동 | F11: 8
A12: 1 | C12: 8 | D12: 오늘 배운 것 확인하기 | E12: 탐구·활동 | F12: 4
D13: 1차시 소계 | F13: =SUM(F5:F12)
A14: 2 | B14: 코드로 구현하고 오류 고치기 | C14: 1 | D14: 코드 실습실 사용법 익히기 | E14: 탐구·활동 | F14: 4
A15: 2 | C15: 2 | D15: 빈칸 채우기 — 공을 날아가게 만들기 | E15: 코딩 미션 | F15: 8
A16: 2 | C16: 3 | D16: 이론값과 맞춰보기 | E16: 코딩 미션 | F16: 6
A17: 2 | C17: 4 | D17: 🔧 디버깅 트랙 — 고장난 코드를 고치세요 | E17: 탐구·활동 | F17: 14
A18: 2 | C18: 5 | D18: 공기저항 넣기 | E18: 코딩 미션 | F18: 10
A19: 2 | C19: 6 | D19: Δt를 바꾸면 오차가 어떻게 변할까 | E19: 탐구·활동 | F19: 6
A20: 2 | C20: 7 | D20: 오늘 배운 것 확인하기 | E20: 탐구·활동 | F20: 2
D21: 2차시 소계 | F21: =SUM(F14:F20)
A22: 3 | B22: 데이터로 최적 조건 찾기 | C22: 1 | D22: 🎯 표적 챌린지 — 감으로 맞혀 보기 | E22: 탐구·활동 | F22: 10
A23: 3 | C23: 2 | D23: 컴퓨터는 몇 번 만에 맞힐까 — 이진 탐색 | E23: 탐구·활동 | F23: 7
A24: 3 | C24: 3 | D24: 전수 탐색으로 데이터 모으기 | E24: 탐구·활동 | F24: 12
A25: 3 | C25: 4 | D25: 그래프를 해석해 봅시다 | E25: 탐구·활동 | F25: 5
A26: 3 | C26: 5 | D26: 1차시의 내 예측과 비교하기 | E26: 탐구·활동 | F26: 5
A27: 3 | C27: 6 | D27: 결론 쓰기 — 왜 최적각이 낮아지는가 | E27: 탐구·활동 | F27: 7
A28: 3 | C28: 7 | D28: 마무리 — 보고서 확인하고 제출하기 | E28: 탐구·활동 | F28: 4
D29: 3차시 소계 | F29: =SUM(F22:F28)
A30: 4 | B30: 실제로 던진 공과 비교하기 | C30: 1 | D30: 실측은 이렇게 합니다 | E30: 탐구·활동 | F30: 6
A31: 4 | C31: 2 | D31: 측정 데이터 불러오기 | E31: 탐구·활동 | F31: 8
A32: 4 | C32: 3 | D32: 교과서 공식은 실제와 맞을까 | E32: 탐구·활동 | F32: 12
A33: 4 | C33: 4 | D33: 왜 뒤쪽에서 더 벗어날까 | E33: 탐구·활동 | F33: 8
A34: 4 | C34: 5 | D34: 두 종류의 오차 구분하기 | E34: 탐구·활동 | F34: 10
A35: 4 | C35: 6 | D35: 다음 시간을 위한 예측 | E35: 서술 작성 | F35: 6
D36: 4차시 소계 | F36: =SUM(F30:F35)
A37: 5 | B37: 실험에서 물리량 끌어내기 (저항계수 구하기) | C37: 1 | D37: 공기저항력의 모형 | E37: 탐구·활동 | F37: 6
A38: 5 | C38: 2 | D38: 손으로 맞춰보기 — k 찾기 | E38: 탐구·활동 | F38: 10
A39: 5 | C39: 3 | D39: 컴퓨터에게 시키기 — 자동 피팅 | E39: 코딩 미션 | F39: 12
A40: 5 | C40: 4 | D40: 찾아낸 k로 물리량 계산하기 | E40: 측정값 제출 | F40: 8
A41: 5 | C41: 5 | D41: 모형 검증 — 다른 실험에도 통할까 | E41: 탐구·활동 | F41: 8
...

Sheet 정보중심_지도안
A1: 정보 중심 과정 — 차시별 지도안
A2: 과목 「정보」 주(主) · 물리(역학과 에너지)는 문제 상황 | 각 차시 합계 50분 (소계는 수식으로 자동 계산)
A4: 차시 | B4: 차시 주제 | C4: 단계 | D4: 단계 활동명 | E4: 단계 유형 | F4: 시간(분)
A5: 1 | B5: 문제 분해와 추상화 — 현실을 계산 가능한 형태로 | C5: 1 | D5: 프로그래머가 받는 것은 "요구사항"입니다 | E5: 탐구·활동 | F5: 6
A6: 1 | C6: 2 | D6: 변수 분류하기 — 입력 / 상태 / 출력 | E6: 탐구·활동 | F6: 12
A7: 1 | C7: 3 | D7: 의사코드 설계하기 | E7: 탐구·활동 | F7: 12
A8: 1 | C8: 4 | D8: 종료 조건을 설계하라 — 무한 루프 막기 | E8: 탐구·활동 | F8: 10
A9: 1 | C9: 5 | D9: 추상화 — 무엇을 버릴 것인가 | E9: 서술 작성 | F9: 10
D10: 1차시 소계 | F10: =SUM(F5:F9)
A11: 2 | B11: 제어 구조와 자료구조로 구현하기 | C11: 1 | D11: 설계를 코드로 옮기는 규칙 | E11: 탐구·활동 | F11: 5
A12: 2 | C12: 2 | D12: 반복문과 상태 갱신 구현하기 | E12: 코딩 미션 | F12: 13
A13: 2 | C13: 3 | D13: 배열을 순회해 통계 내기 | E13: 코딩 미션 | F13: 12
A14: 2 | C14: 4 | D14: while 과 for — 어느 것을 쓸까 | E14: 탐구·활동 | F14: 12
A15: 2 | C15: 5 | D15: 오늘 만든 코드를 말로 설명하기 | E15: 서술 작성 | F15: 8
D16: 2차시 소계 | F16: =SUM(F11:F15)
A17: 3 | B17: 디버깅과 테스트 — 틀린 코드를 찾아내는 기술 | C17: 1 | D17: 버그는 실패가 아니라 일과입니다 | E17: 탐구·활동 | F17: 6
A18: 3 | C18: 2 | D18: 🔧 디버깅 트랙 — 세 개의 버그 | E18: 탐구·활동 | F18: 20
A19: 3 | C19: 3 | D19: 테스트 케이스 설계하기 | E19: 탐구·활동 | F19: 12
A20: 3 | C20: 4 | D20: 버그 리포트 작성하기 | E20: 서술 작성 | F20: 12
D21: 3차시 소계 | F21: =SUM(F17:F20)
A22: 4 | B22: 자료 처리 — 외부 데이터를 읽고, 다루고, 보여주기 | C22: 1 | D22: 프로그램은 데이터를 먹고 삽니다 | E22: 탐구·활동 | F22: 6
A23: 4 | C23: 2 | D23: 데이터 불러오기 | E23: 탐구·활동 | F23: 8
A24: 4 | C24: 3 | D24: 문자열 파싱 함수 만들기 | E24: 코딩 미션 | F24: 14
A25: 4 | C25: 4 | D25: 통계 함수 만들기 — 평균·최대·오차 | E25: 코딩 미션 | F25: 14
A26: 4 | C26: 5 | D26: 수치를 그림으로 — 시각화가 하는 일 | E26: 탐구·활동 | F26: 8
D27: 4차시 소계 | F27: =SUM(F22:F26)
A28: 5 | B28: 탐색 알고리즘과 계산 복잡도 | C28: 1 | D28: 표적 맞히기 — 사람은 어떻게 찾는가 | E28: 탐구·활동 | F28: 10
A29: 5 | C29: 2 | D29: 전수 탐색 구현하기 | E29: 코딩 미션 | F29: 14
A30: 5 | C30: 3 | D30: 이진 탐색 구현하기 | E30: 코딩 미션 | F30: 14
A31: 5 | C31: 4 | D31: 복잡도 — 얼마나 빨리 느려지는가 | E31: 탐구·활동 | F31: 12
D32: 5차시 소계 | F32: =SUM(F28:F31)
A33: 6 | B33: 최적화 — 데이터에 가장 잘 맞는 값 찾기 | C33: 1 | D33: 이번엔 답을 모릅니다 | E33: 탐구·활동 | F33: 6
A34: 6 | C34: 2 | D34: ① 사람이 직접 찾아보기 | E34: 탐구·활동 | F34: 8
A35: 6 | C35: 3 | D35: ② 격자 탐색 구현하기 | E35: 코딩 미션 | F35: 14
A36: 6 | C36: 4 | D36: ③ 삼분 탐색 — 더 적은 계산으로 | E36: 탐구·활동 | F36: 12
A37: 6 | C37: 5 | D37: 세 방법 비교 보고서 | E37: 서술 작성 | F37: 10
D38: 6차시 소계 | F38: =SUM(F33:F37)
A39: 7 | B39: 함수와 모듈화 — 한 번 만들어 여러 곳에 쓰기 | C39: 1 | D39: 복사·붙여넣기의 대가 | E39: 탐구·활동 | F39: 8
A40: 7 | C40: 2 | D40: 범용 시뮬레이션 엔진 만들기 | E40: 코딩 미션 | F40: 16
A41: 7 | C41: 3 | D41: 같은 엔진에 힘을 갈아 끼우기 | E41: 탐구·활동 | F41: 14
...

Sheet 성취기준_매핑
A1: 성취기준 매핑 (2022 개정 교육과정)
A2: 물리는 교육부 고시 「역학과 에너지」 원문과 대조 완료. 정보는 대조 자료가 없어 확인이 필요합니다.
A4: 과정 | B4: 차시 | C4: 과목 | D4: 성취기준 번호 | E4: 성취기준 내용(요지) | F4: 해당 활동 | G4: 확인 상태
A5: 물리 중심 | B5: 1~4·7 | C5: 역학과 에너지 | D5: [12역학01-02] | E5: 뉴턴 운동 법칙을 이용하여 물체의 포물선 운동을 정량적으로 설명하고, 포물선 운동에서의 역학적 에너지를 구할 수 있다. | F5: 1-2~1-5 탐구 / 2-2~2-3 구현 / 4-3 실측 대조 / 7-2 에너지 계산 | G5: 원문 대조 완료
A6: 물리 중심 | B6: 2·3·5 | C6: 역학과 에너지 | D6: [12역학01-01] | E6: 물체에 작용하는 여러 가지 힘의 합력을 구하여 물체의 운동을 정량적으로 예측할 수 있다. | F6: 2-5 중력+저항 합력 / 3-3 저항과 사거리 / 5-2~5-4 저항계수 산출 | G6: 원문 대조 완료
A7: 물리 중심 | B7: 6 | C7: 역학과 에너지 | D7: [12역학03-01] | E7: 용수철 진자를 통해 단진동을 이해하고, 가속도와 변위 사이의 관계를 설명할 수 있다. | F7: 6-2 단진동 구현 / 6-3 주기와 질량의 관계 | G7: 원문 대조 완료
A8: 물리 중심 | B8: 6 | C8: 역학과 에너지 | D8: [12역학01-04] | E8: 케플러 법칙으로부터 중력의 존재가 밝혀지는 과학사적 배경을 이해하고, 중력을 이용하여 인공위성과 행성의 운동을 분석하고 설명할 수 있다. | F8: 6-4 행성 궤도 구현 / 6-5 면적 속도 일정(케플러 제2법칙) | G8: 원문 대조 완료
A9: 물리 중심 | B9: 7 | C9: 역학과 에너지 | D9: [12역학01-05] | E9: 역학적 에너지 보존을 이용하여 행성에 따라 탈출 속도가 다름을 이해하고, 운동량 보존을 이용하여 우주선이 궤도에 오르는 원리를 설명할 수 있다. | F9: 7-3 에너지 드리프트 / 7-5 저항이 한 일 | G9: 원문 대조 완료
A10: 물리 중심 | B10: 1 | C10: 정보 | D10: [12정03-01] | E10: 실생활 문제를 분석하여 핵심 요소를 추출하고 알고리즘으로 설계한다. | F10: 1-6 의사코드 / 1-7 손계산 | G10: 확인 필요
A11: 물리 중심 | B11: 2 | C11: 정보 | D11: [12정03-05] | E11: 다양한 제어 구조와 자료구조를 활용하여 문제 해결 프로그램을 작성한다. | F11: 2-2~2-3 구현 | G11: 확인 필요
A12: 물리 중심 | B12: 2 | C12: 정보 | D12: [12정03-02] | E12: 프로그램의 오류를 발견하고 수정한다. | F12: 2-4 디버깅 트랙(버그 3종) | G12: 확인 필요
A13: 물리 중심 | B13: 3·5 | C13: 정보 | D13: [12정03-03] | E13: 탐색 알고리즘을 이해하고 문제 상황에 적절히 적용한다. | F13: 3-2 이진 탐색 / 3-3 전수 탐색 / 5-3 자동 피팅 | G13: 확인 필요
A14: 물리 중심 | B14: 8 | C14: 공통 | D14: (번호 미정) | E14: 탐구 과정을 설계·수행하고 결과를 논거와 함께 발표한다. | F14: 8-2~8-6 프로젝트·발표 | G14: 확인 필요
A15: 정보 중심 | B15: 1 | C15: 정보 | D15: [12정03-01] | E15: 실생활 문제를 분석하여 핵심 요소를 추출하고 알고리즘으로 설계한다. | F15: i1-2 변수 분류 / i1-3 의사코드 | G15: 확인 필요
... A23: 정보 중심 | B23: 2~7 | C23: 역학과 에너지 | D23: [12역학01-02] | E23: (소재로 활용) 포물선 운동을 정량적으로 설명하고 역학적 에너지를 구할 수 있다. | F23: 전 차시의 문제 상황으로 사용 | G23: 원문 대조 완료
A25: 출처 및 확인 상태
A26: · 출처 : 교육부 고시 2022 개정 교육과정 과학과 교육과정 「역학과 에너지」. 교육과정 고시문은 공공저작물이며 저작권자는 교육부입니다. 출처를 밝히면 이용할 수 있습니다. ⑴ 시공간과 운동 / ⑶ 탄성파와 소리 영역의 성취기준 원문과 대조하여 확인했습니다. · 정보 : 대조할 원문 자료가 없어 번호를 확정하지 못했습니다. 국가교육과정정보센터(NCIC)에서 고등학교 「정보」 성취기준 번호를 확인해 주십시오. · 「역학과 에너지」 ⑴ 시공간과 운동 영역의 탐구 활동에는 다음이 명시되어 있어 본 수업의 4·6·7차시와 직접 대응합니다 : - 포물선 운동을 하는 물체의 동영상을 분석하여 역학적 에너지 보존 확인하기 - 스마트폰을 이용하여 다양한 놀이 기구의 운동 분석하기 - 행성 관측 데이터를 이용하여 케플러 법칙 확인하기

Sheet 성취수준_평가기준
A1: 성취수준(A~E)과 평가기준
A2: 수업 중 도달 지점을 수준별로 설계했습니다. 대응 단계는 웹앱의 단계 번호입니다.
A4: 수준 | B4: 성취수준 진술 | C4: 도달 증거 | D4: 대응 단계(물리) | E4: 대응 단계(정보)
A5: A | B5: 모형을 알고리즘으로 완전히 전환하고, 결과를 물리 법칙으로 해석하며 알고리즘의 효율성까지 비교·판단한다. | C5: 힌트 없이 버그를 수정하고, 최적각 이동을 체공시간 관점에서 논증한다. | D5: 2-4 무힌트, 7-3, 8-4 | E5: i6-4, i7-2, i8-5
A6: B | B6: 모형을 알고리즘으로 전환해 프로그램을 완성하고 결과의 경향성을 설명한다. | C6: 공기저항 구현까지 통과하고 데이터로 결론을 제시한다. | D6: 2-5, 3-3, 5-3 | E6: i5-2, i5-3, i6-3
A7: C | B7: 안내된 절차에 따라 프로그램을 완성하고 결과를 읽어 낸다. | C7: 힌트를 참고해 기본 구현을 통과하고 표에서 최적값을 찾는다. | D7: 2-3, 3-3 | E7: i2-3, i4-4
A8: D | B8: 제시된 코드를 수정·실행하여 부분적으로 결과를 얻는다. | C8: 빈칸을 채워 공을 날리고 슬라이더 관찰을 기록한다. | D8: 1-2, 2-2 | E8: i2-2, i4-2
A9: E | B9: 안내를 받아 시뮬레이션을 실행하고 현상을 관찰한다. | C9: 각도별 궤적 차이를 말로 설명한다. | D9: 1-2 ~ 1-4 | E9: i1-2, i1-4
A11: 평가기준 (성취기준별 상·중·하)
A12: 성취기준 | B12: 수준 | C12: 평가기준
A13: [12정03-01] 알고리즘 설계 | B13: 상 | C13: 초기조건·반복조건·종료조건·갱신순서를 모두 정확히 포함한 의사코드를 스스로 작성한다.
B14: 중 | C14: 주요 단계를 포함하나 종료조건이나 갱신 순서에 일부 오류가 있다.
B15: 하 | C15: 제시된 단계를 순서대로 배열할 수 있다.
A16: [12정03-02] 오류 수정 | B16: 상 | C16: 증상만 보고 원인을 특정하여 세 버그를 모두 힌트 없이 수정한다.
B17: 중 | C17: 힌트를 활용하여 버그를 수정하고 원인을 설명한다.
B18: 하 | C18: 안내에 따라 지정된 줄을 고쳐 실행 결과를 얻는다.
A19: [12물리01-04] 저항력의 영향 | B19: 상 | C19: 최적 발사각이 낮아지는 현상을 체공시간·속력 감소의 인과로 설명한다.
B20: 중 | C20: 저항이 커지면 사거리가 줄고 최적각이 내려감을 데이터로 제시한다.
B21: 하 | C21: 저항이 있으면 공이 덜 멀리 나간다는 것을 관찰하여 진술한다.

Sheet 평가기록(양식)
A1: 학생별 평가 기록 양식
A2: 노란색 칸만 입력하십시오. 합계·비율·성취수준은 수식으로 자동 계산됩니다.
A4: 입력 안내
A5: · B열 학번, C열 이름, D열 과정("물리중심" 또는 "정보중심")을 입력합니다. · E~L열에는 각 차시에서 학생이 통과한 단계 수를 입력합니다. · M열 합계, N열 달성률, O열 성취수준은 자동 계산되므로 입력하지 마십시오. · 10행은 작성 예시입니다. 실제 기록은 11행부터 입력하고 10행은 지워도 됩니다. · 성취수준 판정 기준(달성률) : A 90% 이상 · B 70% 이상 · C 50% 이상 · D 30% 이상 · E 30% 미만
A9: No | B9: 학번 | C9: 이름 | D9: 과정 | E9: 1차시 | F9: 2차시 | G9: 3차시 | H9: 4차시 | I9: 5차시 | J9: 6차시 | K9: 7차시 | L9: 8차시 | M9: 통과 합계 | N9: 달성률 | O9: 성취수준 | R9: 과정별 총 단계 수 (판정 기준)
A10: 1 | B10: 10101 | C10: 홍길동 | D10: 물리중심 | E10: 8 | F10: 7 | G10: 7 | H10: 6 | I10: 6 | J10: 6 | K10: 6 | L10: 6 | M10: =IF(COUNT(E10:L10)=0,"",SUM(E10:L10)) | N10: =IFERROR(IF($M10="","",$M10/IF($D10="정보중심",$S$11,$S$10)),"") | O10: =IF($N10="","",IF($N10>=0.9,"A",IF($N10>=0.7,"B",IF($N10>=0.5,"C",IF($N10>=0.3,"D","E"))))) | R10: 물리중심 | S10: 52
A11: 2 | M11: =IF(COUNT(E11:L11)=0,"",SUM(E11:L11)) | N11: =IFERROR(IF($M11="","",$M11/IF($D11="정보중심",$S$11,$S$10)),"") | O11: =IF($N11="","",IF($N11>=0.9,"A",IF($N11>=0.7,"B",IF($N11>=0.5,"C",IF($N11>=0.3,"D","E"))))) | R11: 정보중심 | S11: 37
A12: 3 | M12: =IF(COUNT(E12:L12)=0,"",SUM(E12:L12)) | N12: =IFERROR(IF($M12="","",$M12/IF($D12="정보중심",$S$11,$S$10)),"") | O12: =IF($N12="","",IF($N12>=0.9,"A",IF($N12>=0.7,"B",IF($N12>=0.5,"C",IF($N12>=0.3,"D","E"))))) | R12: ※ 웹앱 소스에서 자동 산출한 값입니다.
A13: 4 | M13: =IF(COUNT(E13:L13)=0,"",SUM(E13:L13)) | N13: =IFERROR(IF($M13="","",$M13/IF($D13="정보중심",$S$11,$S$10)),"") | O13: =IF($N13="","",IF($N13>=0.9,"A",IF($N13>=0.7,"B",IF($N13>=0.5,"C",IF($N13>=0.3,"D","E")))))
A14: 5 | M14: =IF(COUNT(E14:L14)=0,"",SUM(E14:L14)) | N14: =IFERROR(IF($M14="","",$M14/IF($D14="정보중심",$S$11,$S$10)),"") | O14: =IF($N14="","",IF($N14>=0.9,"A",IF($N14>=0.7,"B",IF($N14>=0.5,"C",IF($N14>=0.3,"D","E")))))
A15: 6 | M15: =IF(COUNT(E15:L15)=0,"",SUM(E15:L15)) | N15: =IFERROR(IF($M15="","",$M15/IF($D15="정보중심",$S$11,$S$10)),"") | O15: =IF($N15="","",IF($N15>=0.9,"A",IF($N15>=0.7,"B",IF($N15>=0.5,"C",IF($N15>=0.3,"D","E")))))
A16: 7 | M16: =IF(COUNT(E16:L16)=0,"",SUM(E16:L16)) | N16: =IFERROR(IF($M16="","",$M16/IF($D16="정보중심",$S$11,$S$10)),"") | O16: =IF($N16="","",IF($N16>=0.9,"A",IF($N16>=0.7,"B",IF($N16>=0.5,"C",IF($N16>=0.3,"D","E")))))
A17: 8 | M17: =IF(COUNT(E17:L17)=0,"",SUM(E17:L17)) | N17: =IFERROR(IF($M17="","",$M17/IF($D17="정보중심",$S$11,$S$10)),"") | O17: =IF($N17="","",IF($N17>=0.9,"A",IF($N17>=0.7,"B",IF($N17>=0.5,"C",IF($N17>=0.3,"D","E")))))
A18: 9 | M18: =IF(COUNT(E18:L18)=0,"",SUM(E18:L18)) | N18: =IFERROR(IF($M18="","",$M18/IF($D18="정보중심",$S$11,$S$10)),"") | O18: =IF($N18="","",IF($N18>=0.9,"A",IF($N18>=0.7,"B",IF($N18>=0.5,"C",IF($N18>=0.3,"D","E")))))
A19: 10 | M19: =IF(COUNT(E19:L19)=0,"",SUM(E19:L19)) | N19: =IFERROR(IF($M19="","",$M19/IF($D19="정보중심",$S$11,$S$10)),"") | O19: =IF($N19="","",IF($N19>=0.9,"A",IF($N19>=0.7,"B",IF($N19>=0.5,"C",IF($N19>=0.3,"D","E")))))
A20: 11 | M20: =IF(COUNT(E20:L20)=0,"",SUM(E20:L20)) | N20: =IFERROR(IF($M20="","",$M20/IF($D20="정보중심",$S$11,$S$10)),"") | O20: =IF($N20="","",IF($N20>=0.9,"A",IF($N20>=0.7,"B",IF($N20>=0.5,"C",IF($N20>=0.3,"D","E")))))
A21: 12 | M21: =IF(COUNT(E21:L21)=0,"",SUM(E21:L21)) | N21: =IFERROR(IF($M21="","",$M21/IF($D21="정보중심",$S$11,$S$10)),"") | O21: =IF($N21="","",IF($N21>=0.9,"A",IF($N21>=0.7,"B",IF($N21>=0.5,"C",IF($N21>=0.3,"D","E")))))
A22: 13 | M22: =IF(COUNT(E22:L22)=0,"",SUM(E22:L22)) | N22: =IFERROR(IF($M22="","",$M22/IF($D22="정보중심",$S$11,$S$10)),"") | O22: =IF($N22="","",IF($N22>=0.9,"A",IF($N22>=0.7,"B",IF($N22>=0.5,"C",IF($N22>=0.3,"D","E")))))
A23: 14 | M23: =IF(COUNT(E23:L23)=0,"",SUM(E23:L23)) | N23: =IFERROR(IF($M23="","",$M23/IF($D23="정보중심",$S$11,$S$10)),"") | O23: =IF($N23="","",IF($N23>=0.9,"A",IF($N23>=0.7,"B",IF($N23>=0.5,"C",IF($N23>=0.3,"D","E")))))
A24: 15 | M24: =IF(COUNT(E24:L24)=0,"",SUM(E24:L24)) | N24: =IFERROR(IF($M24="","",$M24/IF($D24="정보중심",$S$11,$S$10)),"") | O24: =IF($N24="","",IF($N24>=0.9,"A",IF($N24>=0.7,"B",IF($N24>=0.5,"C",IF($N24>=0.3,"D","E")))))
... A40: 31 | M40: =IF(COUNT(E40:L40)=0,"",SUM(E40:L40)) | N40: =IFERROR(IF($M40="","",$M40/IF($D40="정보중심",$S$11,$S$10)),"") | O40: =IF($N40="","",IF($N40>=0.9,"A",IF($N40>=0.7,"B",IF($N40>=0.5,"C",IF($N40>=0.3,"D","E")))))
